[12/Apr/2020 03:20:22] ERROR [django.request:228] Internal Server Error: /donation/update_chart
Traceback (most recent call last):
  File "/Users/jishin/Documents/Project/BetoajRecipe/venv/lib/python3.7/site-packages/django/core/handlers/exception.py", line 34, in inner
    response = get_response(request)
  File "/Users/jishin/Documents/Project/BetoajRecipe/venv/lib/python3.7/site-packages/django/core/handlers/base.py", line 115, in _get_response
    response = self.process_exception_by_middleware(e, request)
  File "/Users/jishin/Documents/Project/BetoajRecipe/venv/lib/python3.7/site-packages/django/core/handlers/base.py", line 113, in _get_response
    response = wrapped_callback(request, *callback_args, **callback_kwargs)
  File "/Users/jishin/Documents/Project/BetoajRecipe/venv/lib/python3.7/site-packages/django/contrib/auth/decorators.py", line 21, in _wrapped_view
    return view_func(request, *args, **kwargs)
  File "/Users/jishin/Documents/Project/BetoajRecipe/project/donate/views.py", line 57, in update_chart
    queryset = Donation.objects.values('donate__time')
  File "/Users/jishin/Documents/Project/BetoajRecipe/venv/lib/python3.7/site-packages/django/db/models/manager.py", line 82, in manager_method
    return getattr(self.get_queryset(), name)(*args, **kwargs)
  File "/Users/jishin/Documents/Project/BetoajRecipe/venv/lib/python3.7/site-packages/django/db/models/query.py", line 809, in values
    clone = self._values(*fields, **expressions)
  File "/Users/jishin/Documents/Project/BetoajRecipe/venv/lib/python3.7/site-packages/django/db/models/query.py", line 804, in _values
    clone.query.set_values(fields)
  File "/Users/jishin/Documents/Project/BetoajRecipe/venv/lib/python3.7/site-packages/django/db/models/sql/query.py", line 2132, in set_values
    self.add_fields(field_names, True)
  File "/Users/jishin/Documents/Project/BetoajRecipe/venv/lib/python3.7/site-packages/django/db/models/sql/query.py", line 1865, in add_fields
    join_info = self.setup_joins(name.split(LOOKUP_SEP), opts, alias, allow_many=allow_m2m)
  File "/Users/jishin/Documents/Project/BetoajRecipe/venv/lib/python3.7/site-packages/django/db/models/sql/query.py", line 1567, in setup_joins
    names[:pivot], opts, allow_many, fail_on_missing=True,
  File "/Users/jishin/Documents/Project/BetoajRecipe/venv/lib/python3.7/site-packages/django/db/models/sql/query.py", line 1483, in names_to_path
    "Choices are: %s" % (name, ", ".join(available)))
django.core.exceptions.FieldError: Cannot resolve keyword 'donate' into field. Choices are: donate_amount, donate_time, donator, donator_id, id
[12/Apr/2020 03:20:22] ERROR [django.server:157] "GET /donation/update_chart HTTP/1.1" 500 16331
[12/Apr/2020 03:20:35] ERROR [django.request:228] Internal Server Error: /donation/charge
Traceback (most recent call last):
  File "/Users/jishin/Documents/Project/BetoajRecipe/venv/lib/python3.7/site-packages/django/core/handlers/exception.py", line 34, in inner
    response = get_response(request)
  File "/Users/jishin/Documents/Project/BetoajRecipe/venv/lib/python3.7/site-packages/django/core/handlers/base.py", line 115, in _get_response
    response = self.process_exception_by_middleware(e, request)
  File "/Users/jishin/Documents/Project/BetoajRecipe/venv/lib/python3.7/site-packages/django/core/handlers/base.py", line 113, in _get_response
    response = wrapped_callback(request, *callback_args, **callback_kwargs)
  File "/Users/jishin/Documents/Project/BetoajRecipe/venv/lib/python3.7/site-packages/django/contrib/auth/decorators.py", line 21, in _wrapped_view
    return view_func(request, *args, **kwargs)
  File "/Users/jishin/Documents/Project/BetoajRecipe/project/donate/views.py", line 21, in charge
    donation = get_object_or_404(Donation)
NameError: name 'get_object_or_404' is not defined
[12/Apr/2020 03:20:35] ERROR [django.server:157] "POST /donation/charge HTTP/1.1" 500 80171
[12/Apr/2020 03:21:13] INFO [django.utils.autoreload:222] /Users/jishin/Documents/Project/BetoajRecipe/project/donate/views.py changed, reloading.
[12/Apr/2020 03:21:14] INFO [django.utils.autoreload:598] Watching for file changes with StatReloader
[12/Apr/2020 03:21:18] INFO [django.server:157] "GET /donation/ HTTP/1.1" 200 13200
[12/Apr/2020 03:21:18] INFO [django.server:157] "GET /static/js/app.js HTTP/1.1" 304 0
[12/Apr/2020 03:21:18] ERROR [django.request:228] Internal Server Error: /donation/update_chart
Traceback (most recent call last):
  File "/Users/jishin/Documents/Project/BetoajRecipe/venv/lib/python3.7/site-packages/django/core/handlers/exception.py", line 34, in inner
    response = get_response(request)
  File "/Users/jishin/Documents/Project/BetoajRecipe/venv/lib/python3.7/site-packages/django/core/handlers/base.py", line 115, in _get_response
    response = self.process_exception_by_middleware(e, request)
  File "/Users/jishin/Documents/Project/BetoajRecipe/venv/lib/python3.7/site-packages/django/core/handlers/base.py", line 113, in _get_response
    response = wrapped_callback(request, *callback_args, **callback_kwargs)
  File "/Users/jishin/Documents/Project/BetoajRecipe/venv/lib/python3.7/site-packages/django/contrib/auth/decorators.py", line 21, in _wrapped_view
    return view_func(request, *args, **kwargs)
  File "/Users/jishin/Documents/Project/BetoajRecipe/project/donate/views.py", line 57, in update_chart
    queryset = Donation.objects.values('donate__time')
  File "/Users/jishin/Documents/Project/BetoajRecipe/venv/lib/python3.7/site-packages/django/db/models/manager.py", line 82, in manager_method
    return getattr(self.get_queryset(), name)(*args, **kwargs)
  File "/Users/jishin/Documents/Project/BetoajRecipe/venv/lib/python3.7/site-packages/django/db/models/query.py", line 809, in values
    clone = self._values(*fields, **expressions)
  File "/Users/jishin/Documents/Project/BetoajRecipe/venv/lib/python3.7/site-packages/django/db/models/query.py", line 804, in _values
    clone.query.set_values(fields)
  File "/Users/jishin/Documents/Project/BetoajRecipe/venv/lib/python3.7/site-packages/django/db/models/sql/query.py", line 2132, in set_values
    self.add_fields(field_names, True)
  File "/Users/jishin/Documents/Project/BetoajRecipe/venv/lib/python3.7/site-packages/django/db/models/sql/query.py", line 1865, in add_fields
    join_info = self.setup_joins(name.split(LOOKUP_SEP), opts, alias, allow_many=allow_m2m)
  File "/Users/jishin/Documents/Project/BetoajRecipe/venv/lib/python3.7/site-packages/django/db/models/sql/query.py", line 1567, in setup_joins
    names[:pivot], opts, allow_many, fail_on_missing=True,
  File "/Users/jishin/Documents/Project/BetoajRecipe/venv/lib/python3.7/site-packages/django/db/models/sql/query.py", line 1483, in names_to_path
    "Choices are: %s" % (name, ", ".join(available)))
django.core.exceptions.FieldError: Cannot resolve keyword 'donate' into field. Choices are: donate_amount, donate_time, donator, donator_id, id
[12/Apr/2020 03:21:18] ERROR [django.server:157] "GET /donation/update_chart HTTP/1.1" 500 16331
[12/Apr/2020 03:21:27] WARNING [django.request:228] Not Found: /donation/charge
[12/Apr/2020 03:21:27] WARNING [django.server:157] "POST /donation/charge HTTP/1.1" 404 11064
[12/Apr/2020 03:26:49] WARNING [django.request:228] Not Found: /donation/charge
[12/Apr/2020 03:26:49] WARNING [django.server:157] "POST /donation/charge HTTP/1.1" 404 11063
[12/Apr/2020 03:31:23] INFO [django.utils.autoreload:222] /Users/jishin/Documents/Project/BetoajRecipe/project/donate/views.py changed, reloading.
[12/Apr/2020 03:31:23] INFO [django.utils.autoreload:598] Watching for file changes with StatReloader
[12/Apr/2020 03:32:15] INFO [django.server:157] "GET /donation/ HTTP/1.1" 200 13200
[12/Apr/2020 03:32:15] INFO [django.server:157] "GET /static/js/app.js HTTP/1.1" 304 0
[12/Apr/2020 03:32:15] ERROR [django.request:228] Internal Server Error: /donation/update_chart
Traceback (most recent call last):
  File "/Users/jishin/Documents/Project/BetoajRecipe/venv/lib/python3.7/site-packages/django/core/handlers/exception.py", line 34, in inner
    response = get_response(request)
  File "/Users/jishin/Documents/Project/BetoajRecipe/venv/lib/python3.7/site-packages/django/core/handlers/base.py", line 115, in _get_response
    response = self.process_exception_by_middleware(e, request)
  File "/Users/jishin/Documents/Project/BetoajRecipe/venv/lib/python3.7/site-packages/django/core/handlers/base.py", line 113, in _get_response
    response = wrapped_callback(request, *callback_args, **callback_kwargs)
  File "/Users/jishin/Documents/Project/BetoajRecipe/venv/lib/python3.7/site-packages/django/contrib/auth/decorators.py", line 21, in _wrapped_view
    return view_func(request, *args, **kwargs)
  File "/Users/jishin/Documents/Project/BetoajRecipe/project/donate/views.py", line 54, in update_chart
    queryset = Donation.objects.values('donate__time')
  File "/Users/jishin/Documents/Project/BetoajRecipe/venv/lib/python3.7/site-packages/django/db/models/manager.py", line 82, in manager_method
    return getattr(self.get_queryset(), name)(*args, **kwargs)
  File "/Users/jishin/Documents/Project/BetoajRecipe/venv/lib/python3.7/site-packages/django/db/models/query.py", line 809, in values
    clone = self._values(*fields, **expressions)
  File "/Users/jishin/Documents/Project/BetoajRecipe/venv/lib/python3.7/site-packages/django/db/models/query.py", line 804, in _values
    clone.query.set_values(fields)
  File "/Users/jishin/Documents/Project/BetoajRecipe/venv/lib/python3.7/site-packages/django/db/models/sql/query.py", line 2132, in set_values
    self.add_fields(field_names, True)
  File "/Users/jishin/Documents/Project/BetoajRecipe/venv/lib/python3.7/site-packages/django/db/models/sql/query.py", line 1865, in add_fields
    join_info = self.setup_joins(name.split(LOOKUP_SEP), opts, alias, allow_many=allow_m2m)
  File "/Users/jishin/Documents/Project/BetoajRecipe/venv/lib/python3.7/site-packages/django/db/models/sql/query.py", line 1567, in setup_joins
    names[:pivot], opts, allow_many, fail_on_missing=True,
  File "/Users/jishin/Documents/Project/BetoajRecipe/venv/lib/python3.7/site-packages/django/db/models/sql/query.py", line 1483, in names_to_path
    "Choices are: %s" % (name, ", ".join(available)))
django.core.exceptions.FieldError: Cannot resolve keyword 'donate' into field. Choices are: donate_amount, donate_time, donator, donator_id, id
[12/Apr/2020 03:32:15] ERROR [django.server:157] "GET /donation/update_chart HTTP/1.1" 500 16331
[12/Apr/2020 03:32:28] ERROR [django.request:228] Internal Server Error: /donation/charge
Traceback (most recent call last):
  File "/Users/jishin/Documents/Project/BetoajRecipe/venv/lib/python3.7/site-packages/django/core/handlers/exception.py", line 34, in inner
    response = get_response(request)
  File "/Users/jishin/Documents/Project/BetoajRecipe/venv/lib/python3.7/site-packages/django/core/handlers/base.py", line 115, in _get_response
    response = self.process_exception_by_middleware(e, request)
  File "/Users/jishin/Documents/Project/BetoajRecipe/venv/lib/python3.7/site-packages/django/core/handlers/base.py", line 113, in _get_response
    response = wrapped_callback(request, *callback_args, **callback_kwargs)
  File "/Users/jishin/Documents/Project/BetoajRecipe/venv/lib/python3.7/site-packages/django/contrib/auth/decorators.py", line 21, in _wrapped_view
    return view_func(request, *args, **kwargs)
  File "/Users/jishin/Documents/Project/BetoajRecipe/project/donate/views.py", line 40, in charge
    donation = Donation.objects.create(donator=request.user, donate_amount=amount, donate_time=now.year)
  File "/Users/jishin/Documents/Project/BetoajRecipe/venv/lib/python3.7/site-packages/django/db/models/manager.py", line 82, in manager_method
    return getattr(self.get_queryset(), name)(*args, **kwargs)
  File "/Users/jishin/Documents/Project/BetoajRecipe/venv/lib/python3.7/site-packages/django/db/models/query.py", line 433, in create
    obj.save(force_insert=True, using=self.db)
  File "/Users/jishin/Documents/Project/BetoajRecipe/venv/lib/python3.7/site-packages/django/db/models/base.py", line 746, in save
    force_update=force_update, update_fields=update_fields)
  File "/Users/jishin/Documents/Project/BetoajRecipe/venv/lib/python3.7/site-packages/django/db/models/base.py", line 784, in save_base
    force_update, using, update_fields,
  File "/Users/jishin/Documents/Project/BetoajRecipe/venv/lib/python3.7/site-packages/django/db/models/base.py", line 887, in _save_table
    results = self._do_insert(cls._base_manager, using, fields, returning_fields, raw)
  File "/Users/jishin/Documents/Project/BetoajRecipe/venv/lib/python3.7/site-packages/django/db/models/base.py", line 926, in _do_insert
    using=using, raw=raw,
  File "/Users/jishin/Documents/Project/BetoajRecipe/venv/lib/python3.7/site-packages/django/db/models/manager.py", line 82, in manager_method
    return getattr(self.get_queryset(), name)(*args, **kwargs)
  File "/Users/jishin/Documents/Project/BetoajRecipe/venv/lib/python3.7/site-packages/django/db/models/query.py", line 1204, in _insert
    return query.get_compiler(using=using).execute_sql(returning_fields)
  File "/Users/jishin/Documents/Project/BetoajRecipe/venv/lib/python3.7/site-packages/django/db/models/sql/compiler.py", line 1390, in execute_sql
    for sql, params in self.as_sql():
  File "/Users/jishin/Documents/Project/BetoajRecipe/venv/lib/python3.7/site-packages/django/db/models/sql/compiler.py", line 1335, in as_sql
    for obj in self.query.objs
  File "/Users/jishin/Documents/Project/BetoajRecipe/venv/lib/python3.7/site-packages/django/db/models/sql/compiler.py", line 1335, in <listcomp>
    for obj in self.query.objs
  File "/Users/jishin/Documents/Project/BetoajRecipe/venv/lib/python3.7/site-packages/django/db/models/sql/compiler.py", line 1334, in <listcomp>
    [self.prepare_value(field, self.pre_save_val(field, obj)) for field in fields]
  File "/Users/jishin/Documents/Project/BetoajRecipe/venv/lib/python3.7/site-packages/django/db/models/sql/compiler.py", line 1275, in prepare_value
    value = field.get_db_prep_save(value, connection=self.connection)
  File "/Users/jishin/Documents/Project/BetoajRecipe/venv/lib/python3.7/site-packages/django/db/models/fields/__init__.py", line 821, in get_db_prep_save
    return self.get_db_prep_value(value, connection=connection, prepared=False)
  File "/Users/jishin/Documents/Project/BetoajRecipe/venv/lib/python3.7/site-packages/django/db/models/fields/__init__.py", line 1376, in get_db_prep_value
    value = self.get_prep_value(value)
  File "/Users/jishin/Documents/Project/BetoajRecipe/venv/lib/python3.7/site-packages/django/db/models/fields/__init__.py", line 1355, in get_prep_value
    value = super().get_prep_value(value)
  File "/Users/jishin/Documents/Project/BetoajRecipe/venv/lib/python3.7/site-packages/django/db/models/fields/__init__.py", line 1215, in get_prep_value
    return self.to_python(value)
  File "/Users/jishin/Documents/Project/BetoajRecipe/venv/lib/python3.7/site-packages/django/db/models/fields/__init__.py", line 1316, in to_python
    parsed = parse_datetime(value)
  File "/Users/jishin/Documents/Project/BetoajRecipe/venv/lib/python3.7/site-packages/django/utils/dateparse.py", line 107, in parse_datetime
    match = datetime_re.match(value)
TypeError: expected string or bytes-like object
[12/Apr/2020 03:32:28] ERROR [django.server:157] "POST /donation/charge HTTP/1.1" 500 175014
[12/Apr/2020 06:41:32] INFO [django.utils.autoreload:222] /Users/jishin/Documents/Project/BetoajRecipe/project/donate/views.py changed, reloading.
[12/Apr/2020 06:41:33] INFO [django.utils.autoreload:598] Watching for file changes with StatReloader
[12/Apr/2020 06:47:34] INFO [django.utils.autoreload:598] Watching for file changes with StatReloader
[12/Apr/2020 06:47:39] INFO [django.server:157] "GET /donation/ HTTP/1.1" 200 13200
[12/Apr/2020 06:47:39] INFO [django.server:157] "GET /static/js/app.js HTTP/1.1" 304 0
[12/Apr/2020 06:47:39] ERROR [django.request:228] Internal Server Error: /donation/update_chart
Traceback (most recent call last):
  File "/Users/jishin/Documents/Project/BetoajRecipe/venv/lib/python3.7/site-packages/django/core/handlers/exception.py", line 34, in inner
    response = get_response(request)
  File "/Users/jishin/Documents/Project/BetoajRecipe/venv/lib/python3.7/site-packages/django/core/handlers/base.py", line 115, in _get_response
    response = self.process_exception_by_middleware(e, request)
  File "/Users/jishin/Documents/Project/BetoajRecipe/venv/lib/python3.7/site-packages/django/core/handlers/base.py", line 113, in _get_response
    response = wrapped_callback(request, *callback_args, **callback_kwargs)
  File "/Users/jishin/Documents/Project/BetoajRecipe/venv/lib/python3.7/site-packages/django/contrib/auth/decorators.py", line 21, in _wrapped_view
    return view_func(request, *args, **kwargs)
  File "/Users/jishin/Documents/Project/BetoajRecipe/project/donate/views.py", line 53, in update_chart
    queryset = Donation.objects.annotate(years=ExtractYear('donate_time')).values('years')
NameError: name 'ExtractYear' is not defined
[12/Apr/2020 06:47:39] ERROR [django.server:157] "GET /donation/update_chart HTTP/1.1" 500 14836
[12/Apr/2020 06:47:50] INFO [django.server:157] "POST /donation/charge HTTP/1.1" 302 0
[12/Apr/2020 06:47:50] INFO [django.server:157] "GET /donation/success HTTP/1.1" 200 12299
[12/Apr/2020 06:47:52] INFO [django.server:157] "GET /donation/ HTTP/1.1" 200 13198
[12/Apr/2020 06:47:52] ERROR [django.request:228] Internal Server Error: /donation/update_chart
Traceback (most recent call last):
  File "/Users/jishin/Documents/Project/BetoajRecipe/venv/lib/python3.7/site-packages/django/core/handlers/exception.py", line 34, in inner
    response = get_response(request)
  File "/Users/jishin/Documents/Project/BetoajRecipe/venv/lib/python3.7/site-packages/django/core/handlers/base.py", line 115, in _get_response
    response = self.process_exception_by_middleware(e, request)
  File "/Users/jishin/Documents/Project/BetoajRecipe/venv/lib/python3.7/site-packages/django/core/handlers/base.py", line 113, in _get_response
    response = wrapped_callback(request, *callback_args, **callback_kwargs)
  File "/Users/jishin/Documents/Project/BetoajRecipe/venv/lib/python3.7/site-packages/django/contrib/auth/decorators.py", line 21, in _wrapped_view
    return view_func(request, *args, **kwargs)
  File "/Users/jishin/Documents/Project/BetoajRecipe/project/donate/views.py", line 53, in update_chart
    queryset = Donation.objects.annotate(years=ExtractYear('donate_time')).values('years')
NameError: name 'ExtractYear' is not defined
[12/Apr/2020 06:47:52] ERROR [django.server:157] "GET /donation/update_chart HTTP/1.1" 500 14836
[12/Apr/2020 06:48:02] WARNING [django.server:157] "GET /static/js/popper.min.js.map HTTP/1.1" 404 1686
[12/Apr/2020 06:48:02] WARNING [django.server:157] "GET /static/js/bootstrap.min.js.map HTTP/1.1" 404 1695
[12/Apr/2020 06:48:02] WARNING [django.server:157] "GET /static/css/bootstrap.min.css.map HTTP/1.1" 404 1701
[12/Apr/2020 06:48:28] ERROR [django.request:228] Internal Server Error: /donation/update_chart
Traceback (most recent call last):
  File "/Users/jishin/Documents/Project/BetoajRecipe/venv/lib/python3.7/site-packages/django/core/handlers/exception.py", line 34, in inner
    response = get_response(request)
  File "/Users/jishin/Documents/Project/BetoajRecipe/venv/lib/python3.7/site-packages/django/core/handlers/base.py", line 115, in _get_response
    response = self.process_exception_by_middleware(e, request)
  File "/Users/jishin/Documents/Project/BetoajRecipe/venv/lib/python3.7/site-packages/django/core/handlers/base.py", line 113, in _get_response
    response = wrapped_callback(request, *callback_args, **callback_kwargs)
  File "/Users/jishin/Documents/Project/BetoajRecipe/venv/lib/python3.7/site-packages/django/contrib/auth/decorators.py", line 21, in _wrapped_view
    return view_func(request, *args, **kwargs)
  File "/Users/jishin/Documents/Project/BetoajRecipe/project/donate/views.py", line 53, in update_chart
    queryset = Donation.objects.annotate(years=ExtractYear('donate_time')).values('years')
NameError: name 'ExtractYear' is not defined
[12/Apr/2020 06:48:29] ERROR [django.server:157] "GET /donation/update_chart HTTP/1.1" 500 79232
[12/Apr/2020 06:49:03] INFO [django.utils.autoreload:222] /Users/jishin/Documents/Project/BetoajRecipe/project/donate/views.py changed, reloading.
[12/Apr/2020 06:49:04] INFO [django.utils.autoreload:598] Watching for file changes with StatReloader
[12/Apr/2020 06:49:12] INFO [django.server:157] "GET /donation/ HTTP/1.1" 200 13200
[12/Apr/2020 06:49:13] WARNING [django.server:157] "GET /static/js/popper.min.js.map HTTP/1.1" 404 1686
[12/Apr/2020 06:49:13] WARNING [django.server:157] "GET /static/js/bootstrap.min.js.map HTTP/1.1" 404 1695
[12/Apr/2020 06:49:13] ERROR [django.request:228] Internal Server Error: /donation/update_chart
Traceback (most recent call last):
  File "/Users/jishin/Documents/Project/BetoajRecipe/venv/lib/python3.7/site-packages/django/core/handlers/exception.py", line 34, in inner
    response = get_response(request)
  File "/Users/jishin/Documents/Project/BetoajRecipe/venv/lib/python3.7/site-packages/django/core/handlers/base.py", line 115, in _get_response
    response = self.process_exception_by_middleware(e, request)
  File "/Users/jishin/Documents/Project/BetoajRecipe/venv/lib/python3.7/site-packages/django/core/handlers/base.py", line 113, in _get_response
    response = wrapped_callback(request, *callback_args, **callback_kwargs)
  File "/Users/jishin/Documents/Project/BetoajRecipe/venv/lib/python3.7/site-packages/django/contrib/auth/decorators.py", line 21, in _wrapped_view
    return view_func(request, *args, **kwargs)
  File "/Users/jishin/Documents/Project/BetoajRecipe/project/donate/views.py", line 56, in update_chart
    years.append(year.donate_time)
AttributeError: 'dict' object has no attribute 'donate_time'
[12/Apr/2020 06:49:13] ERROR [django.server:157] "GET /donation/update_chart HTTP/1.1" 500 14812
[12/Apr/2020 06:49:13] WARNING [django.server:157] "GET /static/css/bootstrap.min.css.map HTTP/1.1" 404 1701
[12/Apr/2020 06:49:19] INFO [django.server:157] "GET /donation/ HTTP/1.1" 200 13198
[12/Apr/2020 06:49:19] WARNING [django.server:157] "GET /static/js/popper.min.js.map HTTP/1.1" 404 1686
[12/Apr/2020 06:49:19] WARNING [django.server:157] "GET /static/js/bootstrap.min.js.map HTTP/1.1" 404 1695
[12/Apr/2020 06:49:19] ERROR [django.request:228] Internal Server Error: /donation/update_chart
Traceback (most recent call last):
  File "/Users/jishin/Documents/Project/BetoajRecipe/venv/lib/python3.7/site-packages/django/core/handlers/exception.py", line 34, in inner
    response = get_response(request)
  File "/Users/jishin/Documents/Project/BetoajRecipe/venv/lib/python3.7/site-packages/django/core/handlers/base.py", line 115, in _get_response
    response = self.process_exception_by_middleware(e, request)
  File "/Users/jishin/Documents/Project/BetoajRecipe/venv/lib/python3.7/site-packages/django/core/handlers/base.py", line 113, in _get_response
    response = wrapped_callback(request, *callback_args, **callback_kwargs)
  File "/Users/jishin/Documents/Project/BetoajRecipe/venv/lib/python3.7/site-packages/django/contrib/auth/decorators.py", line 21, in _wrapped_view
    return view_func(request, *args, **kwargs)
  File "/Users/jishin/Documents/Project/BetoajRecipe/project/donate/views.py", line 56, in update_chart
    years.append(year.donate_time)
AttributeError: 'dict' object has no attribute 'donate_time'
[12/Apr/2020 06:49:19] ERROR [django.server:157] "GET /donation/update_chart HTTP/1.1" 500 14812
[12/Apr/2020 06:49:19] WARNING [django.server:157] "GET /static/css/bootstrap.min.css.map HTTP/1.1" 404 1701
[12/Apr/2020 06:50:10] INFO [django.server:157] "GET /donation/ HTTP/1.1" 200 13266
[12/Apr/2020 06:50:10] WARNING [django.server:157] "GET /static/css/bootstrap.min.css.map HTTP/1.1" 404 1701
[12/Apr/2020 06:50:10] WARNING [django.server:157] "GET /static/js/popper.min.js.map HTTP/1.1" 404 1686
[12/Apr/2020 06:50:10] WARNING [django.server:157] "GET /static/js/bootstrap.min.js.map HTTP/1.1" 404 1695
[12/Apr/2020 06:50:10] ERROR [django.request:228] Internal Server Error: /donation/update_chart
Traceback (most recent call last):
  File "/Users/jishin/Documents/Project/BetoajRecipe/venv/lib/python3.7/site-packages/django/core/handlers/exception.py", line 34, in inner
    response = get_response(request)
  File "/Users/jishin/Documents/Project/BetoajRecipe/venv/lib/python3.7/site-packages/django/core/handlers/base.py", line 115, in _get_response
    response = self.process_exception_by_middleware(e, request)
  File "/Users/jishin/Documents/Project/BetoajRecipe/venv/lib/python3.7/site-packages/django/core/handlers/base.py", line 113, in _get_response
    response = wrapped_callback(request, *callback_args, **callback_kwargs)
  File "/Users/jishin/Documents/Project/BetoajRecipe/venv/lib/python3.7/site-packages/django/contrib/auth/decorators.py", line 21, in _wrapped_view
    return view_func(request, *args, **kwargs)
  File "/Users/jishin/Documents/Project/BetoajRecipe/project/donate/views.py", line 56, in update_chart
    years.append(year.donate_time)
AttributeError: 'dict' object has no attribute 'donate_time'
[12/Apr/2020 06:50:10] ERROR [django.server:157] "GET /donation/update_chart HTTP/1.1" 500 14812
[12/Apr/2020 06:50:32] INFO [django.server:157] "GET /donation/ HTTP/1.1" 200 13266
[12/Apr/2020 06:50:32] WARNING [django.server:157] "GET /static/css/bootstrap.min.css.map HTTP/1.1" 404 1701
[12/Apr/2020 06:50:32] WARNING [django.server:157] "GET /static/js/bootstrap.min.js.map HTTP/1.1" 404 1695
[12/Apr/2020 06:50:32] WARNING [django.server:157] "GET /static/js/popper.min.js.map HTTP/1.1" 404 1686
[12/Apr/2020 06:50:39] ERROR [django.request:228] Internal Server Error: /donation/update_chart
Traceback (most recent call last):
  File "/Users/jishin/Documents/Project/BetoajRecipe/venv/lib/python3.7/site-packages/django/core/handlers/exception.py", line 34, in inner
    response = get_response(request)
  File "/Users/jishin/Documents/Project/BetoajRecipe/venv/lib/python3.7/site-packages/django/core/handlers/base.py", line 115, in _get_response
    response = self.process_exception_by_middleware(e, request)
  File "/Users/jishin/Documents/Project/BetoajRecipe/venv/lib/python3.7/site-packages/django/core/handlers/base.py", line 113, in _get_response
    response = wrapped_callback(request, *callback_args, **callback_kwargs)
  File "/Users/jishin/Documents/Project/BetoajRecipe/venv/lib/python3.7/site-packages/django/contrib/auth/decorators.py", line 21, in _wrapped_view
    return view_func(request, *args, **kwargs)
  File "/Users/jishin/Documents/Project/BetoajRecipe/project/donate/views.py", line 56, in update_chart
    years.append(year.donate_time)
AttributeError: 'dict' object has no attribute 'donate_time'
[12/Apr/2020 06:50:39] ERROR [django.server:157] "GET /donation/update_chart HTTP/1.1" 500 14812
[12/Apr/2020 06:52:10] INFO [django.server:157] "GET /donation/ HTTP/1.1" 200 13266
[12/Apr/2020 06:52:10] ERROR [django.request:228] Internal Server Error: /donation/update_chart
Traceback (most recent call last):
  File "/Users/jishin/Documents/Project/BetoajRecipe/venv/lib/python3.7/site-packages/django/core/handlers/exception.py", line 34, in inner
    response = get_response(request)
  File "/Users/jishin/Documents/Project/BetoajRecipe/venv/lib/python3.7/site-packages/django/core/handlers/base.py", line 115, in _get_response
    response = self.process_exception_by_middleware(e, request)
  File "/Users/jishin/Documents/Project/BetoajRecipe/venv/lib/python3.7/site-packages/django/core/handlers/base.py", line 113, in _get_response
    response = wrapped_callback(request, *callback_args, **callback_kwargs)
  File "/Users/jishin/Documents/Project/BetoajRecipe/venv/lib/python3.7/site-packages/django/contrib/auth/decorators.py", line 21, in _wrapped_view
    return view_func(request, *args, **kwargs)
  File "/Users/jishin/Documents/Project/BetoajRecipe/project/donate/views.py", line 56, in update_chart
    years.append(year.donate_time)
AttributeError: 'dict' object has no attribute 'donate_time'
[12/Apr/2020 06:52:10] ERROR [django.server:157] "GET /donation/update_chart HTTP/1.1" 500 14812
[12/Apr/2020 06:52:15] WARNING [django.server:157] "GET /static/js/popper.min.js.map HTTP/1.1" 404 1686
[12/Apr/2020 06:52:15] WARNING [django.server:157] "GET /static/js/bootstrap.min.js.map HTTP/1.1" 404 1695
[12/Apr/2020 06:52:15] WARNING [django.server:157] "GET /static/css/bootstrap.min.css.map HTTP/1.1" 404 1701
[12/Apr/2020 07:13:56] ERROR [django.request:228] Internal Server Error: /donation/update_chart
Traceback (most recent call last):
  File "/Users/jishin/Documents/Project/BetoajRecipe/venv/lib/python3.7/site-packages/django/core/handlers/exception.py", line 34, in inner
    response = get_response(request)
  File "/Users/jishin/Documents/Project/BetoajRecipe/venv/lib/python3.7/site-packages/django/core/handlers/base.py", line 115, in _get_response
    response = self.process_exception_by_middleware(e, request)
  File "/Users/jishin/Documents/Project/BetoajRecipe/venv/lib/python3.7/site-packages/django/core/handlers/base.py", line 113, in _get_response
    response = wrapped_callback(request, *callback_args, **callback_kwargs)
  File "/Users/jishin/Documents/Project/BetoajRecipe/venv/lib/python3.7/site-packages/django/contrib/auth/decorators.py", line 21, in _wrapped_view
    return view_func(request, *args, **kwargs)
  File "/Users/jishin/Documents/Project/BetoajRecipe/project/donate/views.py", line 56, in update_chart
    years.append(year.donate_time)
AttributeError: 'dict' object has no attribute 'donate_time'
[12/Apr/2020 07:13:56] ERROR [django.server:157] "GET /donation/update_chart HTTP/1.1" 500 79781
[12/Apr/2020 07:14:45] INFO [django.utils.autoreload:222] /Users/jishin/Documents/Project/BetoajRecipe/project/donate/views.py changed, reloading.
[12/Apr/2020 07:14:46] INFO [django.utils.autoreload:598] Watching for file changes with StatReloader
[12/Apr/2020 07:14:59] INFO [django.server:157] "GET /donation/ HTTP/1.1" 200 13268
[12/Apr/2020 07:14:59] INFO [django.server:157] "GET /static/js/app.js HTTP/1.1" 200 3759
[12/Apr/2020 07:14:59] WARNING [django.server:157] "GET /static/js/popper.min.js.map HTTP/1.1" 404 1686
[12/Apr/2020 07:14:59] WARNING [django.server:157] "GET /static/js/bootstrap.min.js.map HTTP/1.1" 404 1695
[12/Apr/2020 07:14:59] WARNING [django.server:157] "GET /static/css/bootstrap.min.css.map HTTP/1.1" 404 1701
[12/Apr/2020 07:15:05] ERROR [django.request:228] Internal Server Error: /donation/update_chart
Traceback (most recent call last):
  File "/Users/jishin/Documents/Project/BetoajRecipe/venv/lib/python3.7/site-packages/django/core/handlers/exception.py", line 34, in inner
    response = get_response(request)
  File "/Users/jishin/Documents/Project/BetoajRecipe/venv/lib/python3.7/site-packages/django/core/handlers/base.py", line 115, in _get_response
    response = self.process_exception_by_middleware(e, request)
  File "/Users/jishin/Documents/Project/BetoajRecipe/venv/lib/python3.7/site-packages/django/core/handlers/base.py", line 113, in _get_response
    response = wrapped_callback(request, *callback_args, **callback_kwargs)
  File "/Users/jishin/Documents/Project/BetoajRecipe/venv/lib/python3.7/site-packages/django/contrib/auth/decorators.py", line 21, in _wrapped_view
    return view_func(request, *args, **kwargs)
  File "/Users/jishin/Documents/Project/BetoajRecipe/project/donate/views.py", line 56, in update_chart
    years.append(year["donate_time"])
KeyError: 'donate_time'
[12/Apr/2020 07:15:05] ERROR [django.server:157] "GET /donation/update_chart HTTP/1.1" 500 14741
[12/Apr/2020 07:15:24] ERROR [django.request:228] Internal Server Error: /donation/update_chart
Traceback (most recent call last):
  File "/Users/jishin/Documents/Project/BetoajRecipe/venv/lib/python3.7/site-packages/django/core/handlers/exception.py", line 34, in inner
    response = get_response(request)
  File "/Users/jishin/Documents/Project/BetoajRecipe/venv/lib/python3.7/site-packages/django/core/handlers/base.py", line 115, in _get_response
    response = self.process_exception_by_middleware(e, request)
  File "/Users/jishin/Documents/Project/BetoajRecipe/venv/lib/python3.7/site-packages/django/core/handlers/base.py", line 113, in _get_response
    response = wrapped_callback(request, *callback_args, **callback_kwargs)
  File "/Users/jishin/Documents/Project/BetoajRecipe/venv/lib/python3.7/site-packages/django/contrib/auth/decorators.py", line 21, in _wrapped_view
    return view_func(request, *args, **kwargs)
  File "/Users/jishin/Documents/Project/BetoajRecipe/project/donate/views.py", line 56, in update_chart
    years.append(year["donate_time"])
KeyError: 'donate_time'
[12/Apr/2020 07:15:24] ERROR [django.server:157] "GET /donation/update_chart HTTP/1.1" 500 79595
[12/Apr/2020 07:16:52] INFO [django.utils.autoreload:222] /Users/jishin/Documents/Project/BetoajRecipe/project/donate/views.py changed, reloading.
[12/Apr/2020 07:16:53] INFO [django.utils.autoreload:598] Watching for file changes with StatReloader
[12/Apr/2020 07:17:01] INFO [django.server:157] "GET /donation/ HTTP/1.1" 200 13268
[12/Apr/2020 07:17:01] WARNING [django.server:157] "GET /static/js/bootstrap.min.js.map HTTP/1.1" 404 1695
[12/Apr/2020 07:17:01] WARNING [django.server:157] "GET /static/js/popper.min.js.map HTTP/1.1" 404 1686
[12/Apr/2020 07:17:01] ERROR [django.request:228] Internal Server Error: /donation/update_chart
Traceback (most recent call last):
  File "/Users/jishin/Documents/Project/BetoajRecipe/venv/lib/python3.7/site-packages/django/core/handlers/exception.py", line 34, in inner
    response = get_response(request)
  File "/Users/jishin/Documents/Project/BetoajRecipe/venv/lib/python3.7/site-packages/django/core/handlers/base.py", line 115, in _get_response
    response = self.process_exception_by_middleware(e, request)
  File "/Users/jishin/Documents/Project/BetoajRecipe/venv/lib/python3.7/site-packages/django/core/handlers/base.py", line 113, in _get_response
    response = wrapped_callback(request, *callback_args, **callback_kwargs)
  File "/Users/jishin/Documents/Project/BetoajRecipe/venv/lib/python3.7/site-packages/django/contrib/auth/decorators.py", line 21, in _wrapped_view
    return view_func(request, *args, **kwargs)
  File "/Users/jishin/Documents/Project/BetoajRecipe/project/donate/views.py", line 61, in update_chart
    queryset = Donation.objects.annotate(years=ExtractYear('donate_time')).values('years').annotate(donate_amount_sum=Sum('donate_amount'))
NameError: name 'Sum' is not defined
[12/Apr/2020 07:17:01] ERROR [django.server:157] "GET /donation/update_chart HTTP/1.1" 500 14869
[12/Apr/2020 07:17:01] WARNING [django.server:157] "GET /static/css/bootstrap.min.css.map HTTP/1.1" 404 1701
[12/Apr/2020 07:17:10] ERROR [django.request:228] Internal Server Error: /donation/update_chart
Traceback (most recent call last):
  File "/Users/jishin/Documents/Project/BetoajRecipe/venv/lib/python3.7/site-packages/django/core/handlers/exception.py", line 34, in inner
    response = get_response(request)
  File "/Users/jishin/Documents/Project/BetoajRecipe/venv/lib/python3.7/site-packages/django/core/handlers/base.py", line 115, in _get_response
    response = self.process_exception_by_middleware(e, request)
  File "/Users/jishin/Documents/Project/BetoajRecipe/venv/lib/python3.7/site-packages/django/core/handlers/base.py", line 113, in _get_response
    response = wrapped_callback(request, *callback_args, **callback_kwargs)
  File "/Users/jishin/Documents/Project/BetoajRecipe/venv/lib/python3.7/site-packages/django/contrib/auth/decorators.py", line 21, in _wrapped_view
    return view_func(request, *args, **kwargs)
  File "/Users/jishin/Documents/Project/BetoajRecipe/project/donate/views.py", line 61, in update_chart
    queryset = Donation.objects.annotate(years=ExtractYear('donate_time')).values('years').annotate(donate_amount_sum=Sum('donate_amount'))
NameError: name 'Sum' is not defined
[12/Apr/2020 07:17:10] ERROR [django.server:157] "GET /donation/update_chart HTTP/1.1" 500 80033
[12/Apr/2020 07:17:51] INFO [django.utils.autoreload:222] /Users/jishin/Documents/Project/BetoajRecipe/project/donate/views.py changed, reloading.
[12/Apr/2020 07:17:51] INFO [django.utils.autoreload:598] Watching for file changes with StatReloader
[12/Apr/2020 07:18:09] INFO [django.server:157] "GET /donation/ HTTP/1.1" 200 13268
[12/Apr/2020 07:18:09] INFO [django.server:157] "GET /static/js/app.js HTTP/1.1" 304 0
[12/Apr/2020 07:18:09] WARNING [django.server:157] "GET /static/js/bootstrap.min.js.map HTTP/1.1" 404 1695
[12/Apr/2020 07:18:09] WARNING [django.server:157] "GET /static/js/popper.min.js.map HTTP/1.1" 404 1686
[12/Apr/2020 07:18:09] WARNING [django.server:157] "GET /static/css/bootstrap.min.css.map HTTP/1.1" 404 1701
[12/Apr/2020 07:18:09] ERROR [django.request:228] Internal Server Error: /donation/update_chart
Traceback (most recent call last):
  File "/Users/jishin/Documents/Project/BetoajRecipe/venv/lib/python3.7/site-packages/django/core/handlers/exception.py", line 34, in inner
    response = get_response(request)
  File "/Users/jishin/Documents/Project/BetoajRecipe/venv/lib/python3.7/site-packages/django/core/handlers/base.py", line 115, in _get_response
    response = self.process_exception_by_middleware(e, request)
  File "/Users/jishin/Documents/Project/BetoajRecipe/venv/lib/python3.7/site-packages/django/core/handlers/base.py", line 113, in _get_response
    response = wrapped_callback(request, *callback_args, **callback_kwargs)
  File "/Users/jishin/Documents/Project/BetoajRecipe/venv/lib/python3.7/site-packages/django/contrib/auth/decorators.py", line 21, in _wrapped_view
    return view_func(request, *args, **kwargs)
  File "/Users/jishin/Documents/Project/BetoajRecipe/project/donate/views.py", line 64, in update_chart
    donate_amount.append(amount.donate_amount_sum)
AttributeError: 'dict' object has no attribute 'donate_amount_sum'
[12/Apr/2020 07:18:09] ERROR [django.server:157] "GET /donation/update_chart HTTP/1.1" 500 14840
[12/Apr/2020 07:18:11] ERROR [django.request:228] Internal Server Error: /donation/update_chart
Traceback (most recent call last):
  File "/Users/jishin/Documents/Project/BetoajRecipe/venv/lib/python3.7/site-packages/django/core/handlers/exception.py", line 34, in inner
    response = get_response(request)
  File "/Users/jishin/Documents/Project/BetoajRecipe/venv/lib/python3.7/site-packages/django/core/handlers/base.py", line 115, in _get_response
    response = self.process_exception_by_middleware(e, request)
  File "/Users/jishin/Documents/Project/BetoajRecipe/venv/lib/python3.7/site-packages/django/core/handlers/base.py", line 113, in _get_response
    response = wrapped_callback(request, *callback_args, **callback_kwargs)
  File "/Users/jishin/Documents/Project/BetoajRecipe/venv/lib/python3.7/site-packages/django/contrib/auth/decorators.py", line 21, in _wrapped_view
    return view_func(request, *args, **kwargs)
  File "/Users/jishin/Documents/Project/BetoajRecipe/project/donate/views.py", line 64, in update_chart
    donate_amount.append(amount.donate_amount_sum)
AttributeError: 'dict' object has no attribute 'donate_amount_sum'
[12/Apr/2020 07:18:12] ERROR [django.server:157] "GET /donation/update_chart HTTP/1.1" 500 80101
[12/Apr/2020 07:18:32] INFO [django.utils.autoreload:222] /Users/jishin/Documents/Project/BetoajRecipe/project/donate/views.py changed, reloading.
[12/Apr/2020 07:18:32] INFO [django.utils.autoreload:598] Watching for file changes with StatReloader
[12/Apr/2020 07:18:39] INFO [django.server:157] "GET /donation/ HTTP/1.1" 200 13268
[12/Apr/2020 07:18:39] WARNING [django.server:157] "GET /static/js/popper.min.js.map HTTP/1.1" 404 1686
[12/Apr/2020 07:18:39] WARNING [django.server:157] "GET /static/js/bootstrap.min.js.map HTTP/1.1" 404 1695
[12/Apr/2020 07:18:39] INFO [django.server:157] "GET /donation/update_chart HTTP/1.1" 200 40
[12/Apr/2020 07:18:39] WARNING [django.server:157] "GET /static/css/bootstrap.min.css.map HTTP/1.1" 404 1701
[12/Apr/2020 07:23:25] INFO [django.server:157] "GET /donation/ HTTP/1.1" 200 13267
[12/Apr/2020 07:23:25] INFO [django.server:157] "GET /static/js/app.js HTTP/1.1" 200 4079
[12/Apr/2020 07:23:25] INFO [django.server:157] "GET /donation/update_chart HTTP/1.1" 200 40
[12/Apr/2020 07:26:45] INFO [django.server:157] "GET /donation/ HTTP/1.1" 200 13266
[12/Apr/2020 07:26:45] INFO [django.server:157] "GET /static/js/app.js HTTP/1.1" 200 4033
[12/Apr/2020 07:26:45] INFO [django.server:157] "GET /donation/update_chart HTTP/1.1" 200 40
[12/Apr/2020 07:27:05] INFO [django.server:157] "GET /donation/ HTTP/1.1" 200 13266
[12/Apr/2020 07:27:05] INFO [django.server:157] "GET /static/js/app.js HTTP/1.1" 200 4075
[12/Apr/2020 07:27:05] INFO [django.server:157] "GET /donation/update_chart HTTP/1.1" 200 40
[12/Apr/2020 07:27:09] WARNING [django.server:157] "GET /static/js/bootstrap.min.js.map HTTP/1.1" 404 1695
[12/Apr/2020 07:27:09] WARNING [django.server:157] "GET /static/js/popper.min.js.map HTTP/1.1" 404 1686
[12/Apr/2020 07:27:09] WARNING [django.server:157] "GET /static/css/bootstrap.min.css.map HTTP/1.1" 404 1701
[12/Apr/2020 07:28:25] INFO [django.server:157] "GET /donation/ HTTP/1.1" 200 13266
[12/Apr/2020 07:28:25] INFO [django.server:157] "GET /static/js/app.js HTTP/1.1" 304 0
[12/Apr/2020 07:28:25] WARNING [django.server:157] "GET /static/js/popper.min.js.map HTTP/1.1" 404 1686
[12/Apr/2020 07:28:25] WARNING [django.server:157] "GET /static/js/bootstrap.min.js.map HTTP/1.1" 404 1695
[12/Apr/2020 07:28:25] INFO [django.server:157] "GET /donation/update_chart HTTP/1.1" 200 40
[12/Apr/2020 07:28:25] WARNING [django.server:157] "GET /static/css/bootstrap.min.css.map HTTP/1.1" 404 1701
[12/Apr/2020 07:28:41] INFO [django.server:157] "GET /donation/ HTTP/1.1" 200 13267
[12/Apr/2020 07:28:41] INFO [django.server:157] "GET /static/js/app.js HTTP/1.1" 200 4079
[12/Apr/2020 07:28:41] WARNING [django.server:157] "GET /static/js/popper.min.js.map HTTP/1.1" 404 1686
[12/Apr/2020 07:28:41] WARNING [django.server:157] "GET /static/js/bootstrap.min.js.map HTTP/1.1" 404 1695
[12/Apr/2020 07:28:41] INFO [django.server:157] "GET /donation/update_chart HTTP/1.1" 200 40
[12/Apr/2020 07:28:41] WARNING [django.server:157] "GET /static/css/bootstrap.min.css.map HTTP/1.1" 404 1701
[12/Apr/2020 07:29:53] INFO [django.utils.autoreload:222] /Users/jishin/Documents/Project/BetoajRecipe/project/donate/views.py changed, reloading.
[12/Apr/2020 07:29:54] INFO [django.utils.autoreload:598] Watching for file changes with StatReloader
[12/Apr/2020 07:29:58] INFO [django.server:157] "GET /donation/ HTTP/1.1" 200 13268
[12/Apr/2020 07:29:58] INFO [django.server:157] "GET /static/js/app.js HTTP/1.1" 304 0
[12/Apr/2020 07:29:58] WARNING [django.server:157] "GET /static/css/bootstrap.min.css.map HTTP/1.1" 404 1701
[12/Apr/2020 07:29:58] WARNING [django.server:157] "GET /static/js/popper.min.js.map HTTP/1.1" 404 1686
[12/Apr/2020 07:29:58] WARNING [django.server:157] "GET /static/js/bootstrap.min.js.map HTTP/1.1" 404 1695
[12/Apr/2020 07:29:58] INFO [django.server:157] "GET /donation/update_chart HTTP/1.1" 200 40
[12/Apr/2020 07:31:37] INFO [django.utils.autoreload:222] /Users/jishin/Documents/Project/BetoajRecipe/project/donate/views.py changed, reloading.
[12/Apr/2020 07:31:37] INFO [django.utils.autoreload:598] Watching for file changes with StatReloader
[12/Apr/2020 07:32:01] INFO [django.server:157] "GET /admin HTTP/1.1" 301 0
[12/Apr/2020 07:32:01] INFO [django.server:157] "GET /admin/ HTTP/1.1" 200 16670
[12/Apr/2020 07:32:01] INFO [django.server:157] "GET /static/admin/css/base.css HTTP/1.1" 200 16378
[12/Apr/2020 07:32:01] INFO [django.server:157] "GET /static/admin/css/dashboard.css HTTP/1.1" 200 412
[12/Apr/2020 07:32:01] INFO [django.server:157] "GET /static/admin/css/responsive.css HTTP/1.1" 200 18052
[12/Apr/2020 07:32:01] INFO [django.server:157] "GET /static/admin/css/fonts.css HTTP/1.1" 200 423
[12/Apr/2020 07:32:01] INFO [django.server:157] "GET /static/admin/img/icon-addlink.svg HTTP/1.1" 200 331
[12/Apr/2020 07:32:01] INFO [django.server:157] "GET /static/admin/img/icon-changelink.svg HTTP/1.1" 200 380
[12/Apr/2020 07:32:01] INFO [django.server:157] "GET /static/admin/fonts/Roboto-Light-webfont.woff HTTP/1.1" 200 85692
[12/Apr/2020 07:32:01] INFO [django.server:157] "GET /static/admin/fonts/Roboto-Regular-webfont.woff HTTP/1.1" 200 85876
[12/Apr/2020 07:32:01] INFO [django.server:157] "GET /static/admin/fonts/Roboto-Bold-webfont.woff HTTP/1.1" 200 86184
[12/Apr/2020 07:32:47] INFO [django.utils.autoreload:222] /Users/jishin/Documents/Project/BetoajRecipe/project/donate/admin.py changed, reloading.
[12/Apr/2020 07:32:47] INFO [django.utils.autoreload:598] Watching for file changes with StatReloader
[12/Apr/2020 07:33:06] INFO [django.utils.autoreload:222] /Users/jishin/Documents/Project/BetoajRecipe/project/donate/admin.py changed, reloading.
[12/Apr/2020 07:33:06] INFO [django.utils.autoreload:598] Watching for file changes with StatReloader
[12/Apr/2020 07:33:12] INFO [django.server:157] "GET /admin/ HTTP/1.1" 200 17356
